Workbook

Sheet Executive_Summary
A1: Phase 3 Data Quality Audit — Executive Summary for Tom Nguyen
A2: Five exports audited: Outpatients (PAS), Inpatients (EHR), ED (EDIS), Theatres (TMS), Workforce (WRS). 4,523 rows, 63 issues logged. All counts are live formulas — see DQ_Issue_Log and Task_Workings.
A4: 1. What is wrong — the errors that change performance figures
A5: ED 4-hour | D5: 35 missing departure times + 9 duplicates + 4 negative times produce three figures: 79.9%, 83.2%, 83.9%. Validated figure: 83.1%.
A6: DNA rate | D6: Status miscoding is small (2 rows). The bigger problem is method and timing: the PAS 14.1% = DNA ÷ (ATT+DNA); DNA outcomes are recorded late (Jan 25.8% → Mar 3.7%). Validated Q1 figure: 13.9% — well above the 8% target.
A7: LWBS | D7: 'LEFT' code (120 rows) is undefined: LWBS is 2.4% or 14.7% depending on its meaning.
A8: ED mortality | D8: 'DIED' on 14.6% of attendances is not credible — likely miscoding. Do not quote any ED mortality figure.
A9: HRG income | D9: 28 blank HRG codes = £51,800 — but over six months, not per month. The brief's £621k/yr figure is overstated ~6×.
A10: Readmissions | D10: 44 blank flags: rate is 9.0%–12.3%, either side of the 10% target.
A11: Theatres | D11: Utilisation_Pct column wrong in 7 rows; 4 rows exceed 100%. The 64% vs 72% dispute is definitional (T4 + overruns).
A12: Agency spend | D12: 15 blank flags + 24 test records. February range: £49,280–£53,515 (narrow — blanks are only 1.4%).
A13: Linkage | D13: No outpatient or ED NHS Number appears in the inpatient file — PAS, EDIS and EHR cannot currently be joined.
A14: NHS Numbers | D14: 188 NHS Numbers start with 0 — opening the CSV in Excel drops the zero. This is the 'truncation' issue.
A16: 2. What you can trust today
A17: KPI | B17: Validated figure | C17: Can we quote it? | D17: Caveat
A18: ED 4-hour | B18: =Task_Workings!B52 -> 0.83135135 | C18: Amber | D18: Quote 83.1% with range 80.1%–83.8% (35 missing departures). Differs from the 81.3% in the brief — reconcile with Sarah's manual count.
A19: DNA rate (Q1, quarterly) | B19: =Task_Workings!B16 -> 0.13919414 | C19: Amber | D19: Quarterly only — monthly figures are distorted by late outcome recording.
A20: HRG coding completeness | B20: =1-Task_Workings!B25 -> 0.97666667 | C20: Green | D20: 97.7% coded vs 98% target; 28 episodes to code.
A21: Theatre utilisation (elective) | B21: =Task_Workings!B60 -> 0.65698479 | C21: Amber | D21: Sessions-based, T1–T3. Definition to be ratified.
A22: Agency spend (Feb) | B22: £49k–£54k | C22: Amber | D22: Range, not a point estimate; reconcile to ledger.
A23: 30-day readmissions | B23: 9.0%–12.3% | C23: Red | D23: 44 blank flags — back-fill before quoting.
A24: LWBS rate | B24: 2.4% or 14.7% | C24: Red | D24: Depends on definition of 'LEFT'.
A25: RTT 18-week | B25: Not from this extract | C25: Red | D25: Outpatient extract holds only 131 open pathways; only 41% of those are within 18 weeks — inconsistent with the 74.8% headline. Needs the full waiting list.
A26: ED mortality / DIED | B26: Do not use | C26: Red | D26: 141 'DIED' codes are not credible.
A28: 3. Priority order for fixing
A29: 1. ED departures and 'DIED'/'LEFT' codes — ED 4-hour is the headline NHS England will test; mortality miscoding is a governance risk.
A30: 2. DNA definition and outcome recording — adopt DNA ÷ (ATT+DNA+REF), report quarterly, 48-hour outcome standard.
A31: 3. HRG blanks (28 episodes) — £51,800 recoverable before the SUS deadline.
A32: 4. NHS Number import as text + PDS back-fill — fixes linkage for readmissions and duplicates.
A33: 5. Readmission flag back-fill — moves RA30 from Unknown to known.
A34: 6. Theatre definition (GIRFT, T1–T3, capped) and TMS session fix.
A35: 7. Workforce: make Agency_Flag mandatory, remove ST-99 test data, escalate 8 shifts over 13 hours to HR.

Sheet DQ_Issue_Log
A1: Issue_ID | B1: Task | C1: 1. Sheet / dataset | D1: Source | E1: 2. Column | F1: 3. Issue type | G1: Issue found | H1: 4. Rows affected | I1: % of rows | J1: 5. Severity | K1: 6. Recommended action | L1: Example record(s) | M1: KPI(s) affected | N1: Impact on the KPI | O1: Root cause (likely) | P1: Owner | Q1: Status
A2: OP-01 | B2: T1 | C2: Outpatients | D2: PAS | E2: Attendance_Status | F2: Non-standard value | G2: Non-standard status values: 'attended' (1) and 'N/A' (1). Valid codes are ATT, DNA, CAN, REF. | H2: =SUMPRODUCT(--(OP_Raw!J2:J581<>""),--ISERROR(MATCH(OP_Raw!J2:J581,{"ATT","DNA","CAN","REF"},0))) -> 2 | I2: =H2/(COUNTA(OP_Raw!A:A)-1) -> 0.0034482759 | J2: Major | K2: Map 'attended' → ATT; exclude 'N/A' (APT-100199 also has CL-DEP, GEN, blank consultant — likely a legacy/test record). Add PAS drop-down validation. | L2: APT-100154 ('attended'); APT-100199 ('N/A') | M2: DNA rate | N2: A COUNTIF on 'ATT' misses 'attended'; 'N/A' inflates any COUNTA denominator. Small here (0.03 pts) but the same pattern at scale drives the DNA dispute. | O2: Free-text entry allowed in PAS status field | P2: PAS team / Sarah Okafor | Q2: Fixed in analysis
A3: OP-02 | B3: T6 | C3: Outpatients | D3: PAS | E3: Waiting_Days | F3: Format error | G3: Text value 'ATT' in a numeric field (column-shift / entry error). | H3: =SUMPRODUCT(--ISTEXT(OP_Raw!K2:K581)) -> 28 | I3: =H3/(COUNTA(OP_Raw!A:A)-1) -> 0.048275862 | J3: Major | K3: Recover from RTT_Weeks × 7 (RTT_Weeks is populated and consistent for every other row). | L3: APT-100362, APT-100369, APT-100375 | M3: RTT, waiting times | N3: Rows drop out of any AVERAGE/SUM of waiting time; Excel may error or silently ignore them. | O3: Status value written into the wrong field on export | P3: Daniel Walsh (pipeline) | Q3: Fixed in analysis
A4: OP-03 | B4: T6 | C4: Outpatients | D4: PAS | E4: Waiting_Days | F4: Impossible value | G4: Negative waiting time. | H4: =COUNTIF(OP_Raw!K2:K581,"<0") -> 1 | I4: =H4/(COUNTA(OP_Raw!A:A)-1) -> 0.0017241379 | J4: Major | K4: Exclude from RTT calculations; validate referral date with PAS team. | L4: APT-100200 (−3 days) | M4: RTT | N4: Impossible value — appointment before referral. Handover notes said 4 rows; this extract has 1. | O4: Referral date entered after appointment date, or transferred-in patient clock | P4: Sarah Okafor | Q4: Open — validate
A5: OP-04 | B5: T2 | C5: Outpatients | D5: PAS | E5: NHS_Number | F5: Blank | G5: NHS Number blank. | H5: =COUNTBLANK(OP_Raw!B2:B581) -> 3 | I5: =H5/(COUNTA(OP_Raw!A:A)-1) -> 0.0051724138 | J5: Major | K5: Trace via PDS (Spine) and back-fill. | L5: 3 rows | M5: Patient matching, RTT | N5: Cannot link to admissions / readmissions; possible duplicate patients on the waiting list. | O5: Not captured at registration | P5: PAS team | Q5: Open
A6: OP-05 | B6: T2 | C6: Outpatients | D6: PAS | E6: NHS_Number | F6: Format error | G6: NHS Numbers starting with 0 — will be truncated to 9 digits if the CSV is opened directly in Excel or cast as INT. | H6: =SUMPRODUCT(--(LEFT(OP_Raw!B2:B581,1)="0")) -> 26 | I6: =H6/(COUNTA(OP_Raw!A:A)-1) -> 0.044827586 | J6: Major | K6: Import NHS_Number as TEXT (Power Query: set type to Text); fix the export query to VARCHAR(10). | L6: APT-100362 (0721302594) | M6: All patient-level KPIs | N6: Root cause of the known 'NHS Number truncation' issue: numeric casting drops the leading zero. | O6: Export casts NHS_Number as INT; Excel auto-converts to number | P6: Daniel Walsh | Q6: Fixed in analysis
A7: OP-06 | B7: T7 | C7: Outpatients | D7: PAS | E7: Specialty_Code | F7: Non-standard value | G7: Retired code GEN (replaced by GM in June 2023). | H7: =COUNTIF(OP_Raw!E2:E581,"GEN") -> 3 | I7: =H7/(COUNTA(OP_Raw!A:A)-1) -> 0.0051724138 | J7: Major | K7: Map GEN → GM using Specialty_Code_Mapping.csv. | L7: 3 rows | M7: Specialty activity, RTT by specialty | N7: General Medicine activity split across two codes and under-reported. | O7: Specialty code migration not completed | P7: Daniel Walsh | Q7: Fixed in analysis
A8: OP-07 | B8: — | C8: Outpatients | D8: PAS | E8: Clinic_Code | F8: Non-standard value | G8: Retired / decommissioned clinic codes CL-OLD and CL-DEP. | H8: =COUNTIF(OP_Raw!G2:G581,"CL-OLD")+COUNTIF(OP_Raw!G2:G581,"CL-DEP") -> 2 | I8: =H8/(COUNTA(OP_Raw!A:A)-1) -> 0.0034482759 | J8: Minor | K8: Exclude from clinic reporting; confirm origin (pre-merger / closed dermatology) with PAS team. | L8: APT-100186 (CL-OLD); APT-100199 (CL-DEP) | M8: Clinic activity, DNA | N8: Activity booked to clinics that no longer exist. | O8: Legacy codes still selectable in PAS | P8: PAS team | Q8: Open — confirm
A9: OP-08 | B9: — | C9: Outpatients | D9: PAS | E9: Consultant_Code | F9: Blank | G9: Consultant code blank. | H9: =COUNTBLANK(OP_Raw!F2:F581) -> 5 | I9: =H9/(COUNTA(OP_Raw!A:A)-1) -> 0.0086206897 | J9: Minor | K9: Report as 'Unknown'; register locums. | L9: APT-100156, APT-100169, APT-100191, APT-100199, APT-100201 | M9: Consultant-level reporting | N9: Cannot attribute activity; possible unregistered locums. | O9: Locum consultants not registered in PAS | P9: Medical Staffing | Q9: Open
A10: OP-09 | B10: T6 | C10: Outpatients | D10: PAS | E10: RTT_Status / RTT_Weeks | F10: Blank | G10: RTT status blank. | H10: =COUNTBLANK(OP_Raw!L2:L581) -> 1 | I10: =H10/(COUNTA(OP_Raw!A:A)-1) -> 0.0017241379 | J10: Major | K10: Validate pathway status. | L10: 1 row | M10: RTT compliance | N10: Pathway cannot be counted as open or closed. | O10: Pathway not validated | P10: Sarah Okafor | Q10: Open
A11: OP-10 | B11: — | C11: Outpatients | D11: PAS | E11: Referral_Source | F11: Non-standard value | G11: Non-standard value 'Other'. | H11: =COUNTIF(OP_Raw!N2:N581,"Other") -> 1 | I11: =H11/(COUNTA(OP_Raw!A:A)-1) -> 0.0017241379 | J11: Minor | K11: Map to reference list. | L11: 1 row | M11: Referral analysis | N11: Minor — not in reference list. | O11: Free text | P11: PAS team | Q11: Open
A12: OP-11 | B12: — | C12: Outpatients | D12: PAS | E12: Postcode | F12: Blank | G12: Postcode blank. | H12: =COUNTBLANK(OP_Raw!O2:O581) -> 2 | I12: =H12/(COUNTA(OP_Raw!A:A)-1) -> 0.0034482759 | J12: Minor | K12: Back-fill from PDS. | L12: 2 rows | M12: Population / health-inequality analysis | N12: Minor. | O12: Not captured | P12: PAS team | Q12: Open
A13: OP-12 | B13: T1 | C13: Outpatients | D13: PAS | E13: Attendance_Status (by month) | F13: Impossible value (implausible pattern) | G13: DNA rate swings from 25.8% (Jan) to 10.9% (Feb) to 3.7% (Mar) — DNA outcomes appear to be recorded late or bulk-updated. | H13: =COUNTIFS(OP_Raw!J2:J581,"DNA",OP_Raw!H2:H581,">="&DATE(2025,1,1),OP_Raw!H2:H581,"<"&DATE(2025,2,1)) -> 49 | I13: =H13/(COUNTA(OP_Raw!A:A)-1) -> 0.084482759 | J13: Major | K13: Report DNA quarterly; set a 48-hour outcome-recording standard for clinics; re-run once March outcomes are complete. | L13: 49 of 76 DNAs fall in January | M13: DNA rate | N13: A calendar-month DNA rate (PAS report method) is unreliable; a quarterly figure is more stable. Explains part of the 3-figure dispute. | O13: Outcome recording lag in clinics | P13: Outpatient Manager / Sarah Okafor | Q13: Open — investigate
A14: OP-13 | B14: T4 | C14: Outpatients | D14: PAS | E14: Appointment_Time | F14: Format error | G14: Placeholder 'TBC' instead of a time. | H14: =COUNTIF(OP_Raw!I2:I581,"TBC") -> 1 | I14: =H14/(COUNTA(OP_Raw!A:A)-1) -> 0.0017241379 | J14: Minor | K14: Confirm slot or exclude. | L14: 1 row | M14: Clinic utilisation | N14: Time arithmetic fails for this row. | O14: Booking without a confirmed slot | P14: PAS team | Q14: Open
A15: OP-14 | B15: T5 | C15: Outpatients | D15: PAS | E15: Appointment_ID | F15: Duplicate | G15: Duplicate check: no exact duplicate IDs and no near-duplicates (tested NHS Number + date; + clinic; + time; Surname + DOB + date). All IDs are valid APT-XXXXXX (no 5-digit truncation). | H15: =ROWS(OP_Raw!A2:A581)-SUMPRODUCT(1/COUNTIF(OP_Raw!A2:A581,OP_Raw!A2:A581)) -> 0 | I15: =H15/(COUNTA(OP_Raw!A:A)-1) -> 0 | J15: None found | K15: No action; keep the check in the weekly pipeline. | L15: None | M15: Activity counts, DNA | N15: None — appointment counts are not inflated by duplicates. | O15: n/a | P15: Analyst | Q15: Closed — none found
A16: IP-01 | B16: — | C16: Inpatients | D16: EHR | E16: Episode_ID | F16: Duplicate | G16: Duplicate Episode_IDs (6 IDs appear twice; 2 exact copies, 4 differ only by Ward_Code). | H16: =ROWS(IP_Raw!A2:A1207)-SUMPRODUCT(1/COUNTIF(IP_Raw!A2:A1207,IP_Raw!A2:A1207)) -> 6 | I16: =H16/(COUNTA(IP_Raw!A:A)-1) -> 0.0049751244 | J16: Major | K16: Keep one row per Episode_ID (first ward); record transfers separately. | L16: EP-10000057, EP-10000091, EP-10000198, EP-10000254, EP-10000264, EP-10000553 | M16: Activity, ALOS, HRG income, bed days | N16: Activity and income double-counted; ward transfers recorded as new episodes. | O16: Ward transfer creates a second record in the EHR export | P16: Daniel Walsh | Q16: Fixed in analysis
A17: IP-02 | B17: T3 | C17: Inpatients | D17: EHR | E17: HRG_Code | F17: Blank | G17: HRG code blank — episode cannot be grouped or paid. | H17: =COUNTBLANK(IP_Raw!M2:M1207) -> 28 | I17: =H17/(COUNTA(IP_Raw!A:A)-1) -> 0.023217247 | J17: Critical | K17: Send Episode_ID list to Clinical Coding before SUS deadline. | L17: 28 episodes (all discharged) | M17: HRG coding completeness, income | N17: £51,800 income at risk (28 × £1,850). NB: across 6 months, not per month as the company brief assumed. | O17: Clinical coding backlog | P17: Marcus Reid (Clinical Coding) | Q17: Open
A18: IP-03 | B18: — | C18: Inpatients | D18: EHR | E18: Readmission_Flag | F18: Blank | G18: Readmission flag blank (handover notes said 41; extract has 44). | H18: =COUNTBLANK(IP_Raw!L2:L1207) -> 44 | I18: =H18/(COUNTA(IP_Raw!A:A)-1) -> 0.036484245 | J18: Major | K18: Back-fill using admission-date logic (NHS Number + admission within 30 days of a previous discharge). | L18: 44 rows | M18: 30-day readmission rate | N18: Rate ranges 9.0% (blanks excluded) to 12.3% (blanks = Y) — straddles the 10% target. | O18: EHR not populating flag; ownership disputed | P18: Analyst (per Nov governance decision) | Q18: Open
A19: IP-04 | B19: T4 | C19: Inpatients | D19: EHR | E19: Discharge_Date / Method / LOS | F19: Blank | G19: Open episodes — no discharge date, method, LOS or bed days. Some admitted in October 2024. | H19: =COUNTBLANK(IP_Raw!I2:I1207) -> 31 | I19: =H19/(COUNTA(IP_Raw!A:A)-1) -> 0.025704809 | J19: Major | K19: Validate each open episode >30 days with ward clerks. | L19: 31 rows (admitted 01/10/2024–08/03/2025) | M19: ALOS, bed occupancy | N19: Excluded from ALOS; very old open episodes are almost certainly missing discharges, which understates bed availability. | O19: Discharge not recorded in EHR | P19: Ward administration | Q19: Open
A20: IP-05 | B20: T4 | C20: Inpatients | D20: EHR | E20: Discharge_Date | F20: Format error | G20: Dates stored as text ('October 9 2024'). | H20: =SUMPRODUCT(--ISTEXT(IP_Raw!I2:I1207)) -> 3 | I20: =H20/(COUNTA(IP_Raw!A:A)-1) -> 0.0024875622 | J20: Major | K20: Convert with Power Query (Date.FromText, locale en-GB). | L20: October 9 2024; November 20 2024; December 19 2024 | M20: ALOS, readmissions | N20: Date arithmetic fails; rows silently drop out. | O20: Manual entry / different source format | P20: Daniel Walsh | Q20: Fixed in analysis
A21: IP-06 | B21: — | C21: Inpatients | D21: EHR | E21: Admission_Type | F21: Non-standard value | G21: Non-standard values 'Elective' (9) and 'emergency' (4). Valid: ELEC, EMER, TRANSFER. | H21: =COUNTIF(IP_Raw!F2:F1207,"Elective")+COUNTIF(IP_Raw!F2:F1207,"emergency") -> 13 | I21: =H21/(COUNTA(IP_Raw!A:A)-1) -> 0.010779436 | J21: Major | K21: Map Elective → ELEC; emergency → EMER. | L21: 13 rows | M21: Elective activity, readmissions, cancelled ops | N21: Elective/emergency counts understated when filtering on code. | O21: Free text entry | P21: Daniel Walsh | Q21: Fixed in analysis
A22: IP-07 | B22: — | C22: Inpatients | D22: EHR | E22: Discharge_Method | F22: Non-standard value | G22: Non-standard value 'Discharged'. | H22: =COUNTIF(IP_Raw!J2:J1207,"Discharged") -> 15 | I22: =H22/(COUNTA(IP_Raw!A:A)-1) -> 0.012437811 | J22: Minor | K22: Map to HOME after validation. | L22: 15 rows | M22: Discharge destination | N22: Cannot tell home vs transfer. | O22: Free text | P22: Ward administration | Q22: Open
A23: IP-08 | B23: — | C23: Inpatients | D23: EHR | E23: Ward_Code | F23: Non-standard value | G23: Decommissioned ward W-08 (closed Feb 2024). | H23: =COUNTIF(IP_Raw!G2:G1207,"W-08") -> 3 | I23: =H23/(COUNTA(IP_Raw!A:A)-1) -> 0.0024875622 | J23: Major | K23: Reassign to correct ward; disable code. | L23: 3 rows | M23: Bed occupancy | N23: Activity on a ward with no beds inflates occupancy. | O23: Legacy code still selectable | P23: Daniel Walsh | Q23: Open
A24: IP-09 | B24: T7 | C24: Inpatients | D24: EHR | E24: Specialty_Code | F24: Non-standard value | G24: Retired code GEN. | H24: =COUNTIF(IP_Raw!H2:H1207,"GEN") -> 10 | I24: =H24/(COUNTA(IP_Raw!A:A)-1) -> 0.008291874 | J24: Major | K24: Map GEN → GM. | L24: 10 rows | M24: Specialty activity | N24: General Medicine under-reported. | O24: Specialty code migration | P24: Daniel Walsh | Q24: Fixed in analysis
A25: IP-10 | B25: — | C25: Inpatients | D25: EHR | E25: Length_of_Stay | F25: Impossible value | G25: Negative length of stay (dates show positive stays). | H25: =COUNTIF(IP_Raw!K2:K1207,"<0") -> 6 | I25: =H25/(COUNTA(IP_Raw!A:A)-1) -> 0.0049751244 | J25: Major | K25: Recalculate LOS = Discharge_Date − Admission_Date. | L25: EP-10000154 (−3 vs 6 days) | M25: ALOS | N25: Pulls ALOS down. | O25: Calculated field error | P25: Daniel Walsh | Q25: Fixed in analysis
A26: IP-11 | B26: — | C26: Inpatients | D26: EHR | E26: Bed_Days | F26: Impossible value | G26: Bed_Days differs from Length_of_Stay. | H26: =SUMPRODUCT(--(IP_Raw!K2:K1207<>""),--(IP_Raw!K2:K1207<>IP_Raw!N2:N1207)) -> 34 | I26: =H26/(COUNTA(IP_Raw!A:A)-1) -> 0.028192371 | J26: Minor | K26: Agree one definition (midnight census). | L26: 34 rows | M26: Bed occupancy, cost per episode | N26: Two 'stay' measures disagree; definition undocumented. | O26: Different counting rules (midnights vs days) | P26: Daniel Walsh | Q26: Open — define
A27: IP-12 | B27: T2 | C27: Inpatients | D27: EHR | E27: NHS_Number | F27: Blank | G27: NHS Number blank. | H27: =COUNTBLANK(IP_Raw!B2:B1207) -> 20 | I27: =H27/(COUNTA(IP_Raw!A:A)-1) -> 0.016583748 | J27: Major | K27: Trace via PDS. | L27: 20 rows | M27: Readmissions, linkage | N27: Readmissions cannot be detected for these patients. | O27: Not captured / unidentified patients | P27: Ward administration | Q27: Open
A28: IP-13 | B28: T2 | C28: Inpatients | D28: EHR | E28: NHS_Number | F28: Format error | G28: NHS Numbers starting with 0 — truncation risk on import. | H28: =SUMPRODUCT(--(LEFT(IP_Raw!B2:B1207,1)="0")) -> 95 | I28: =H28/(COUNTA(IP_Raw!A:A)-1) -> 0.078772803 | J28: Major | K28: Import as Text. | L28: EP rows with 0-leading NHS Number | M28: Readmissions, linkage | N28: Truncated numbers break patient matching. | O28: INT casting | P28: Daniel Walsh | Q28: Fixed in analysis
A29: IP-14 | B29: T3 | C29: Inpatients | D29: EHR | E29: Consultant / ICD10 / OPCS4 | F29: Blank | G29: Consultant (28), ICD-10 (27) and OPCS-4 (27) blank. | H29: =COUNTBLANK(IP_Raw!P2:P1207) -> 27 | I29: =H29/(COUNTA(IP_Raw!A:A)-1) -> 0.02238806 | J29: Critical | K29: Include in Clinical Coding work list. | L29: 25 episodes have an HRG but no ICD-10 code | M29: HRG income, SUS | N29: Episodes with missing diagnosis/procedure codes may group incorrectly. | O29: Coding incomplete | P29: Marcus Reid | Q29: Open
A30: ED-01 | B30: — | C30: ED | D30: EDIS | E30: Attendance_ID | F30: Duplicate | G30: Duplicate attendance IDs (9 duplicated records). | H30: =ROWS(ED_Raw!A2:A970)-SUMPRODUCT(1/COUNTIF(ED_Raw!A2:A970,ED_Raw!A2:A970)) -> 9 | I30: =H30/(COUNTA(ED_Raw!A:A)-1) -> 0.0092879257 | J30: Critical | K30: De-duplicate on Attendance_ID. | L30: ED-7000110, ED-7000114, ED-7000213 … | M30: ED 4-hour, attendances | N30: Attendances double-counted. | O30: Export duplication | P30: Daniel Walsh | Q30: Fixed in analysis
A31: ED-02 | B31: T4 | C31: ED | D31: EDIS | E31: Departure_Time | F31: Blank | G31: Departure time missing — so Total_ED_Time and Four_Hour_Breach are also blank. | H31: =COUNTBLANK(ED_Raw!I2:I970) -> 35 | I31: =H31/(COUNTA(ED_Raw!A:A)-1) -> 0.036119711 | J31: Critical | K31: Report validated figure with blanks excluded and show the range; chase departures with ED. | L31: 35 rows | M31: ED 4-hour | N31: The root cause of the three ED figures: 79.9% (blanks = breach), 83.2% (blanks excluded), 83.9% (blanks = pass). | O31: Departure not recorded (incl. EDIS downtime) | P31: ED Manager | Q31: Open
A32: ED-03 | B32: — | C32: ED | D32: EDIS | E32: Four_Hour_Breach | F32: Blank | G32: Breach flag blank (35 missing departures + 4 negative times). | H32: =COUNTBLANK(ED_Raw!K2:K970) -> 39 | I32: =H32/(COUNTA(ED_Raw!A:A)-1) -> 0.040247678 | J32: Critical | K32: Recalculate breach from times (helper column Q). | L32: 39 rows | M32: ED 4-hour | N32: As above. | O32: Flag derived from a missing/invalid time | P32: Analyst | Q32: Fixed in analysis
A33: ED-04 | B33: — | C33: ED | D33: EDIS | E33: Total_ED_Time_Minutes | F33: Impossible value | G33: Negative ED time — midnight / calculation error. | H33: =COUNTIF(ED_Raw!L2:L970,"<0") -> 4 | I33: =H33/(COUNTA(ED_Raw!A:A)-1) -> 0.004127967 | J33: Major | K33: Recalculate from Arrival/Departure times. | L33: ED-7000256 (−57; times give 166 min) | M33: ED 4-hour | N33: 4 attendances missing from the breach count; recalculation shows 1 is a breach (369 min). | O33: Derived field error | P33: Daniel Walsh | Q33: Fixed in analysis
A34: ED-05 | B34: T4 | C34: ED | D34: EDIS | E34: Arrival_Time | F34: Format error | G34: 12-hour AM/PM format ('3:53 PM') instead of 24-hour HH:MM. | H34: =SUMPRODUCT(--ISNUMBER(SEARCH("M",ED_Raw!F2:F970))) -> 17 | I34: =H34/(COUNTA(ED_Raw!A:A)-1) -> 0.01754386 | J34: Major | K34: Convert with TIMEVALUE / Power Query. | L34: 17 rows | M34: ED 4-hour | N34: Time arithmetic fails unless converted. | O34: Manual entry (EDIS downtime pattern) | P34: Daniel Walsh | Q34: Fixed in analysis
A35: ED-06 | B35: — | C35: ED | D35: EDIS | E35: Triage_Category | F35: Impossible value | G35: Invalid triage values 0 and 6 (valid 1–5). | H35: =COUNTIF(ED_Raw!G2:G970,0)+COUNTIF(ED_Raw!G2:G970,6) -> 9 | I35: =H35/(COUNTA(ED_Raw!A:A)-1) -> 0.0092879257 | J35: Major | K35: Review with ED; add 1–5 validation. | L35: ED-7000206, ED-7000228, ED-7000358 … | M35: Acuity / casemix | N35: Clinical prioritisation unknown for these patients. | O35: No validation in EDIS | P35: ED Manager | Q35: Open
A36: ED-07 | B36: — | C36: ED | D36: EDIS | E36: Seen_by_Clinician_Time | F36: Blank | G36: Time seen by clinician blank. | H36: =COUNTBLANK(ED_Raw!H2:H970) -> 28 | I36: =H36/(COUNTA(ED_Raw!A:A)-1) -> 0.028895769 | J36: Minor | K36: Chase with ED. | L36: 28 rows | M36: Time to clinician, LWBS | N36: Cannot measure wait to be seen. | O36: Not recorded | P36: ED Manager | Q36: Open
A37: ED-08 | B37: T2 | C37: ED | D37: EDIS | E37: NHS_Number | F37: Blank | G37: NHS Number blank (12.5% of attendances). | H37: =COUNTBLANK(ED_Raw!B2:B970) -> 121 | I37: =H37/(COUNTA(ED_Raw!A:A)-1) -> 0.124871 | J37: Major | K37: Back-fill post-attendance via PDS. | L37: 121 rows | M37: Linkage to admissions / readmissions | N37: Cannot link ED attendances to inpatient episodes. | O37: Unidentified patients at arrival | P37: ED reception | Q37: Open
A38: ED-09 | B38: — | C38: ED | D38: EDIS | E38: Departure_Code | F38: Non-standard value | G38: Code 'LEFT' (120 rows) not in the glossary — ambiguous vs LWBS (23). | H38: =COUNTIF(ED_Raw!J2:J970,"LEFT") -> 120 | I38: =H38/(COUNTA(ED_Raw!A:A)-1) -> 0.12383901 | J38: Major | K38: Define LEFT with ED (left before or after being seen?) and map. | L38: 120 rows | M38: LWBS rate | N38: LWBS is 2.4% (LWBS only) or 14.7% (LWBS + LEFT) — the difference between meeting and badly breaching the 5% standard. | O38: Code list not controlled | P38: ED Manager / Daniel Walsh | Q38: Open — define
A39: ED-10 | B39: — | C39: ED | D39: EDIS | E39: Departure_Code | F39: Impossible value | G39: 'DIED' recorded for 14.6% of attendances — clinically implausible for an ED. | H39: =COUNTIF(ED_Raw!J2:J970,"DIED") -> 141 | I39: =H39/(COUNTA(ED_Raw!A:A)-1) -> 0.14551084 | J39: Critical | K39: Urgent validation with ED and Medical Director before any mortality reporting. | L39: 141 rows | M39: Mortality, quality reporting | N39: Must not be quoted; likely miscoding. | O39: Wrong code mapping in EDIS export | P39: Medical Director / Daniel Walsh | Q39: Open — urgent
A40: ED-11 | B40: — | C40: ED | D40: EDIS | E40: Chief_Complaint | F40: Non-standard value | G40: Inconsistent case ('STROKE', 'Chest Pain', 'laceration') — 48 variants of 21 complaints. | H40: =SUMPRODUCT(--NOT(EXACT(ED_Raw!M2:M970,UPPER(ED_Raw!M2:M970)))) -> 698 | I40: =H40/(COUNTA(ED_Raw!A:A)-1) -> 0.72033024 | J40: Minor | K40: Standardise with UPPER/TRIM in Power Query. | L40: 'abdominal pain' vs 'ABDOMINAL PAIN' | M40: Casemix analysis | N40: Grouping splits the same complaint. | O40: Free text | P40: Analyst | Q40: Fixed in analysis
...

Sheet DQ_Scores
A1: Data Quality Scores by dataset
A2: DQ score = share of rows with no issue from the DQ_Issue_Log. Rows with ≥1 issue counted by the Python audit (each row counted once, even with several issues).
A4: Dataset | B4: Source | C4: Raw sheet | D4: Total rows | E4: Rows with ≥1 issue | F4: DQ score | G4: Issues logged | H4: Critical / Major issues | I4: RAG | J4: Headline problem
A5: Outpatients | B5: PAS | C5: OP_Raw | D5: =COUNTA(OP_Raw!A:A)-1 -> 580 | E5: 40 | F5: =1-E5/D5 -> 0.93103448 | G5: =COUNTIF(DQ_Issue_Log!$C$2:$C$64,A5) -> 14 | H5: =COUNTIFS(DQ_Issue_Log!$C$2:$C$64,A5,DQ_Issue_Log!$J$2:$J$64,"Critical")+COUNTIFS(DQ_Issue_Log!$C$2:$C$64,A5,DQ_Issue_Log!$J$2:$J$64,"Major") -> 8 | I5: =IF(F5>=0.95,"Green",IF(F5>=0.85,"Amber","Red")) -> Amber | J5: Small number of status/ID errors, but DNA outcomes recorded late (monthly DNA swings 25.8% → 3.7%).
A6: Inpatients | B6: EHR | C6: IP_Raw | D6: =COUNTA(IP_Raw!A:A)-1 -> 1206 | E6: 270 | F6: =1-E6/D6 -> 0.7761194 | G6: =COUNTIF(DQ_Issue_Log!$C$2:$C$64,A6) -> 14 | H6: =COUNTIFS(DQ_Issue_Log!$C$2:$C$64,A6,DQ_Issue_Log!$J$2:$J$64,"Critical")+COUNTIFS(DQ_Issue_Log!$C$2:$C$64,A6,DQ_Issue_Log!$J$2:$J$64,"Major") -> 12 | I6: =IF(F6>=0.95,"Green",IF(F6>=0.85,"Amber","Red")) -> Red | J6: 28 blank HRG codes (£51,800), 44 blank readmission flags, duplicates and 31 open episodes.
A7: ED | B7: EDIS | C7: ED_Raw | D7: =COUNTA(ED_Raw!A:A)-1 -> 969 | E7: 431 | F7: =1-E7/D7 -> 0.55521156 | G7: =COUNTIF(DQ_Issue_Log!$C$2:$C$64,A7) -> 12 | H7: =COUNTIFS(DQ_Issue_Log!$C$2:$C$64,A7,DQ_Issue_Log!$J$2:$J$64,"Critical")+COUNTIFS(DQ_Issue_Log!$C$2:$C$64,A7,DQ_Issue_Log!$J$2:$J$64,"Major") -> 9 | I7: =IF(F7>=0.95,"Green",IF(F7>=0.85,"Amber","Red")) -> Red | J7: 35 missing departures cause the 3 ED figures; 'DIED' and 'LEFT' codes are not credible.
A8: Theatres | B8: TMS | C8: TH_Raw | D8: =COUNTA(TH_Raw!A:A)-1 -> 208 | E8: 87 | F8: =1-E8/D8 -> 0.58173077 | G8: =COUNTIF(DQ_Issue_Log!$C$2:$C$64,A8) -> 10 | H8: =COUNTIFS(DQ_Issue_Log!$C$2:$C$64,A8,DQ_Issue_Log!$J$2:$J$64,"Critical")+COUNTIFS(DQ_Issue_Log!$C$2:$C$64,A8,DQ_Issue_Log!$J$2:$J$64,"Major") -> 3 | I8: =IF(F8>=0.95,"Green",IF(F8>=0.85,"Amber","Red")) -> Red | J8: 7 wrong Utilisation_Pct values, 4 rows over 100%, no agreed definition.
A9: Workforce | B9: WRS | C9: WF_Raw | D9: =COUNTA(WF_Raw!A:A)-1 -> 1560 | E9: 102 | F9: =1-E9/D9 -> 0.93461538 | G9: =COUNTIF(DQ_Issue_Log!$C$2:$C$64,A9) -> 11 | H9: =COUNTIFS(DQ_Issue_Log!$C$2:$C$64,A9,DQ_Issue_Log!$J$2:$J$64,"Critical")+COUNTIFS(DQ_Issue_Log!$C$2:$C$64,A9,DQ_Issue_Log!$J$2:$J$64,"Major") -> 4 | I9: =IF(F9>=0.95,"Green",IF(F9>=0.85,"Amber","Red")) -> Amber | J9: 15 blank agency flags, 24 test records, 8 shifts breaching 13 hours.
A10: Overall | D10: =SUM(D5:D9) -> 4523 | E10: =SUM(E5:E9) -> 930 | F10: =1-E10/D10 -> 0.79438426 | G10: =SUM(G5:G9) -> 61 | H10: =SUM(H5:H9) -> 36 | I10: =IF(F10>=0.95,"Green",IF(F10>=0.85,"Amber","Red")) -> Red
A12: RAG thresholds (Task 14 / IG standard): Green ≥95% · Amber 85–94% · Red <85% of rows valid. Cross-sheet linkage issues (XS) are not counted in any one dataset. Note: NHS Numbers in this test extract do not pass the Modulus 11 check digit, so that check is excluded here — apply it to live data.

Sheet Date_Format_Audit
A1: Task 4 — Date and time format audit (Sheets 1–3)
A2: Standard: dates dd/mm/yyyy (stored as real Excel dates); times HH:MM (24-hour). Dates that Excel could not read are stored as text, so ISTEXT finds them.
A4: Sheet | B4: Column | C4: Expected format | D4: Non-standard values | E4: Examples | F4: Issue type | G4: Severity | H4: Recommended action
A5: Outpatients | B5: Patient_DOB | C5: dd/mm/yyyy | D5: =SUMPRODUCT(--ISTEXT(OP_Raw!D2:D581)) -> 0 | E5: None | F5: — | G5: None found | H5: No action.
A6: Outpatients | B6: Appointment_Date | C6: dd/mm/yyyy | D6: =SUMPRODUCT(--ISTEXT(OP_Raw!H2:H581)) -> 0 | E6: None | F6: — | G6: None found | H6: No action.
A7: Outpatients | B7: Appointment_Time | C7: HH:MM | D7: =SUMPRODUCT(--(OP_Raw!I2:I581<>""),--((LEN(OP_Raw!I2:I581)<>5)+(MID(OP_Raw!I2:I581,3,1)<>":")>0)) -> 1 | E7: 'TBC' | F7: Format error | G7: Minor | H7: Confirm the slot or exclude from clinic-time analysis.
A8: Inpatients | B8: Patient_DOB | C8: dd/mm/yyyy | D8: =SUMPRODUCT(--ISTEXT(IP_Raw!D2:D1207)) -> 0 | E8: None | F8: — | G8: None found | H8: No action.
A9: Inpatients | B9: Admission_Date | C9: dd/mm/yyyy | D9: =SUMPRODUCT(--ISTEXT(IP_Raw!E2:E1207)) -> 0 | E9: None | F9: — | G9: None found | H9: No action.
A10: Inpatients | B10: Discharge_Date | C10: dd/mm/yyyy | D10: =SUMPRODUCT(--ISTEXT(IP_Raw!I2:I1207)) -> 3 | E10: 'October 9 2024', 'November 20 2024', 'December 19 2024' | F10: Format error | G10: Major | H10: Convert in Power Query (Date.FromText, en-GB); recalculate LOS; stop free-text entry.
A11: ED | B11: Patient_DOB | C11: dd/mm/yyyy | D11: =SUMPRODUCT(--ISTEXT(ED_Raw!D2:D970)) -> 0 | E11: None | F11: — | G11: None found | H11: No action.
A12: ED | B12: Arrival_Date | C12: dd/mm/yyyy | D12: =SUMPRODUCT(--ISTEXT(ED_Raw!E2:E970)) -> 0 | E12: None | F12: — | G12: None found | H12: No action.
A13: ED | B13: Arrival_Time | C13: HH:MM | D13: =SUMPRODUCT(--(ED_Raw!F2:F970<>""),--((LEN(ED_Raw!F2:F970)<>5)+(MID(ED_Raw!F2:F970,3,1)<>":")>0)) -> 17 | E13: '3:53 PM', '12:13 AM', '2:43 PM' | F13: Format error | G13: Major | H13: Convert 12-hour to 24-hour (TIMEVALUE / Power Query Time.FromText); then recalculate ED minutes and breach flag.
A14: ED | B14: Seen_by_Clinician_Time | C14: HH:MM | D14: =SUMPRODUCT(--(ED_Raw!H2:H970<>""),--((LEN(ED_Raw!H2:H970)<>5)+(MID(ED_Raw!H2:H970,3,1)<>":")>0)) -> 0 | E14: None | F14: — | G14: None found | H14: No action (28 blanks logged separately).
A15: ED | B15: Departure_Time | C15: HH:MM | D15: =SUMPRODUCT(--(ED_Raw!I2:I970<>""),--((LEN(ED_Raw!I2:I970)<>5)+(MID(ED_Raw!I2:I970,3,1)<>":")>0)) -> 0 | E15: None | F15: — | G15: None found | H15: No action (35 blanks logged separately).
A17: Also checked: no impossible dates (e.g. 31/02), no future dates beyond 31/03/2025, all DOBs between 1935 and 2007. Theatre Week_Ending has 2 non-Sunday dates (logged as TH issue).

Sheet GEN_Audit
A1: Task 7 — GEN → GM replacement audit trail
A2: Original columns are untouched; replacement is done in a Specialty_Code_Clean helper column on each raw sheet so every change is traceable.
A4: Sheet | B4: Column | C4: GEN before | D4: GM before | E4: GEN after | F4: GM after | G4: Check: GM after = GM before + GEN before | H4: Change date | I4: Changed by | J4: Authority
A5: Outpatients (OP_Raw) | B5: Specialty_Code | C5: =COUNTIF(OP_Raw!E2:E581,"GEN") -> 3 | D5: =COUNTIF(OP_Raw!E2:E581,"GM") -> 55 | E5: =COUNTIF(OP_Raw!R2:R581,"GEN") -> 0 | F5: =COUNTIF(OP_Raw!R2:R581,"GM") -> 58 | G5: =IF(AND(E5=0,F5=D5+C5),"PASS","FAIL") -> PASS | H5: Week 1 | I5: L. Ukeni | J5: Specialty_Code_Mapping.csv (Daniel Walsh)
A6: Inpatients (IP_Raw) | B6: Specialty_Code | C6: =COUNTIF(IP_Raw!H2:H1207,"GEN") -> 10 | D6: =COUNTIF(IP_Raw!H2:H1207,"GM") -> 98 | E6: =COUNTIF(IP_Raw!R2:R1207,"GEN") -> 0 | F6: =COUNTIF(IP_Raw!R2:R1207,"GM") -> 108 | G6: =IF(AND(E6=0,F6=D6+C6),"PASS","FAIL") -> PASS | H6: Week 1 | I6: L. Ukeni | J6: Specialty_Code_Mapping.csv (Daniel Walsh)
A7: ED (ED_Raw) | B7: Specialty_Referred | C7: =COUNTIF(ED_Raw!N2:N970,"GEN") -> 0 | D7: =COUNTIF(ED_Raw!N2:N970,"GM") -> 15 | E7: =C7 -> 0 | F7: =D7 -> 15 | G7: =IF(AND(E7=0,F7=D7+C7),"PASS","FAIL") -> PASS | H7: Week 1 | I7: L. Ukeni | J7: Specialty_Code_Mapping.csv (Daniel Walsh)
A8: Theatres (TH_Raw) | B8: Specialty_Code | C8: =COUNTIF(TH_Raw!K2:K209,"GEN") -> 2 | D8: =COUNTIF(TH_Raw!K2:K209,"GM") -> 0 | E8: =COUNTIF(TH_Raw!L2:L209,"GEN") -> 0 | F8: =COUNTIF(TH_Raw!L2:L209,"GM") -> 2 | G8: =IF(AND(E8=0,F8=D8+C8),"PASS","FAIL") -> PASS | H8: Week 1 | I8: L. Ukeni | J8: Specialty_Code_Mapping.csv (Daniel Walsh)
A9: Workforce (WF_Raw) | B9: Specialty_Code | C9: =COUNTIF(WF_Raw!L2:L1561,"GEN") -> 9 | D9: =COUNTIF(WF_Raw!L2:L1561,"GM") -> 281 | E9: =COUNTIF(WF_Raw!M2:M1561,"GEN") -> 0 | F9: =COUNTIF(WF_Raw!M2:M1561,"GM") -> 290 | G9: =IF(AND(E9=0,F9=D9+C9),"PASS","FAIL") -> PASS | H9: Week 1 | I9: L. Ukeni | J9: Specialty_Code_Mapping.csv (Daniel Walsh)
A10: Total | C10: =SUM(C5:C9) -> 24 | D10: =SUM(D5:D9) -> 449 | E10: =SUM(E5:E9) -> 0 | F10: =SUM(F5:F9) -> 473

Sheet Task_Workings
A1: Task workings — every figure is a live formula on the raw sheets
A3: TASK 1 — Attendance status check (Sarah Okafor)
A4: ATT (exact match) | B4: =SUMPRODUCT(--EXACT(OP_Raw!J2:J581,"ATT")) -> 463
A5: DNA (exact match) | B5: =SUMPRODUCT(--EXACT(OP_Raw!J2:J581,"DNA")) -> 76
A6: CAN (exact match) | B6: =SUMPRODUCT(--EXACT(OP_Raw!J2:J581,"CAN")) -> 33
A7: REF (exact match) | B7: =SUMPRODUCT(--EXACT(OP_Raw!J2:J581,"REF")) -> 6
A8: 'attended' — should be ATT | B8: =SUMPRODUCT(--EXACT(OP_Raw!J2:J581,"attended")) -> 1 | C8: APT-100154
A9: 'N/A' — exclude | B9: =SUMPRODUCT(--EXACT(OP_Raw!J2:J581,"N/A")) -> 1 | C9: APT-100199 — also CL-DEP clinic, GEN specialty, blank consultant: likely legacy/test record
A10: Total rows | B10: =COUNTA(OP_Raw!J2:J581) -> 580
A12: DNA rate reconciliation (for the Board conflict — Sarah vs Priya)
A13: Version A logic: COUNTIF(DNA) ÷ COUNTA(column incl. header) | B13: =B5/(COUNTA(OP_Raw!J2:J581)+1) -> 0.13080895 | C13: Header row and CAN rows in the denominator
A14: DNA ÷ all appointments (raw) | B14: =B5/COUNTA(OP_Raw!J2:J581) -> 0.13103448 | C14: Includes cancellations
A15: PAS-style: DNA ÷ (ATT + DNA) | B15: =B5/(B4+B5) -> 0.14100186 | C15: Reproduces the 14.1% PAS figure — but uncorrected statuses and excludes REF
A16: VALIDATED (recommended): DNA ÷ (ATT + 'attended' + DNA + REF) | B16: =B5/(B4+B8+B5+B7) -> 0.13919414 | C16: NHS England definition: denominator excludes cancellations; 'attended' corrected; 'N/A' excluded
A17: Trust target | B17: 0.08 | C17: Company brief
A18: DNA rate — January 2025 | B18: =COUNTIFS(OP_Raw!J2:J581,"DNA",OP_Raw!H2:H581,">="&DATE(2025,1,1),OP_Raw!H2:H581,"<"&DATE(2025,2,1))/(COUNTIFS(OP_Raw!J2:J581,"ATT",OP_Raw!H2:H581,">="&DATE(2025,1,1),OP_Raw!H2:H581,"<"&DATE(2025,2,1))+COUNTIFS(OP_Raw!J2:J581,"attended",OP_Raw!H2:H581,">="&DATE(2025,1,1),OP_Raw!H2:H581,"<"&DATE(2025,2,1))+COUNTIFS(OP_Raw!J2:J581,"DNA",OP_Raw!H2:H581,">="&DATE(2025,1,1),OP_Raw!H2:H581,"<"&DATE(2025,2,1))+COUNTIFS(OP_Raw!J2:J581,"REF",OP_Raw!H2:H581,">="&DATE(2025,1,1),OP_Raw!H2:H581,"<"&DATE(2025,2,1))) -> 0.25789474 | C18: Monthly swing 25.8% → 3.7% indicates late outcome recording — report quarterly
A19: DNA rate — February 2025 | B19: =COUNTIFS(OP_Raw!J2:J581,"DNA",OP_Raw!H2:H581,">="&DATE(2025,2,1),OP_Raw!H2:H581,"<"&DATE(2025,3,1))/(COUNTIFS(OP_Raw!J2:J581,"ATT",OP_Raw!H2:H581,">="&DATE(2025,2,1),OP_Raw!H2:H581,"<"&DATE(2025,3,1))+COUNTIFS(OP_Raw!J2:J581,"attended",OP_Raw!H2:H581,">="&DATE(2025,2,1),OP_Raw!H2:H581,"<"&DATE(2025,3,1))+COUNTIFS(OP_Raw!J2:J581,"DNA",OP_Raw!H2:H581,">="&DATE(2025,2,1),OP_Raw!H2:H581,"<"&DATE(2025,3,1))+COUNTIFS(OP_Raw!J2:J581,"REF",OP_Raw!H2:H581,">="&DATE(2025,2,1),OP_Raw!H2:H581,"<"&DATE(2025,3,1))) -> 0.10880829
A20: DNA rate — March 2025 | B20: =COUNTIFS(OP_Raw!J2:J581,"DNA",OP_Raw!H2:H581,">="&DATE(2025,3,1),OP_Raw!H2:H581,"<"&DATE(2025,4,1))/(COUNTIFS(OP_Raw!J2:J581,"ATT",OP_Raw!H2:H581,">="&DATE(2025,3,1),OP_Raw!H2:H581,"<"&DATE(2025,4,1))+COUNTIFS(OP_Raw!J2:J581,"attended",OP_Raw!H2:H581,">="&DATE(2025,3,1),OP_Raw!H2:H581,"<"&DATE(2025,4,1))+COUNTIFS(OP_Raw!J2:J581,"DNA",OP_Raw!H2:H581,">="&DATE(2025,3,1),OP_Raw!H2:H581,"<"&DATE(2025,4,1))+COUNTIFS(OP_Raw!J2:J581,"REF",OP_Raw!H2:H581,">="&DATE(2025,3,1),OP_Raw!H2:H581,"<"&DATE(2025,4,1))) -> 0.036809816
A22: TASK 3 — HRG blanks (Priya Chakrabarti)
A23: Blank HRG_Code (rows) | B23: =COUNTBLANK(IP_Raw!M2:M1207) -> 28 | C23: All 28 are on unique, discharged episodes — none sit in duplicate rows
A24: Unique episodes (duplicates removed) | B24: =SUMPRODUCT(1/COUNTIF(IP_Raw!A2:A1207,IP_Raw!A2:A1207)) -> 1200 | C24: 1,206 rows − 6 duplicate Episode_IDs
A25: % of episodes uncoded | B25: =B23/B24 -> 0.023333333 | C25: Target 98% coded → actual 97.7%
A26: Tariff per episode (£) | B26: 1850 | C26: Supplied by Priya
A27: Of which admitted in March 2025 (may still be in coding window) | B27: =COUNTIFS(IP_Raw!M2:M1207,"",IP_Raw!E2:E1207,">="&DATE(2025,3,1)) -> 4
A28: Best case — exclude March (coding backlog, recoverable) | B28: =(B23-B27)*B26 -> 44400
A29: Central — all blanks unpaid | B29: =B23*B26 -> 51800
A30: Worst case — plus 25 episodes with HRG but no ICD-10 (may group wrongly) | B30: =(B23+SUMPRODUCT(--(IP_Raw!M2:M1207<>""),--(IP_Raw!P2:P1207="")))*B26 -> 98050 | C30: Upper bound; these may be paid at the wrong HRG rather than not at all
A31: Months covered by the extract | B31: 6 | C31: Oct 2024 – Mar 2025
A32: Average per month (central) | B32: =B23*B26/B31 -> 8633.3333 | C32: Brief assumed £51,800 PER MONTH — the extract shows £51,800 over SIX months (≈£8.6k/month)
A34: TASK 8 — Agency spend range, February 2025 (Priya Chakrabarti)
A35: Period start | B35: 45689 | C35: Latest complete month (export ends 02/03/2025)
A36: Period end | B36: 45716
A37: Valid shifts (ST-99 test records excluded) | B37: =COUNTIFS(WF_Raw!B2:B1561,"<>ST-99*",WF_Raw!E2:E1561,">="&B35,WF_Raw!E2:E1561,"<="&B36) -> 782
A38: Agency_Flag = Y | B38: =COUNTIFS(WF_Raw!B2:B1561,"<>ST-99*",WF_Raw!E2:E1561,">="&B35,WF_Raw!E2:E1561,"<="&B36,WF_Raw!I2:I1561,"Y") -> 128
A39: Agency_Flag = N | B39: =COUNTIFS(WF_Raw!B2:B1561,"<>ST-99*",WF_Raw!E2:E1561,">="&B35,WF_Raw!E2:E1561,"<="&B36,WF_Raw!I2:I1561,"N") -> 643
A40: Agency_Flag blank | B40: =COUNTIFS(WF_Raw!B2:B1561,"<>ST-99*",WF_Raw!E2:E1561,">="&B35,WF_Raw!E2:E1561,"<="&B36,WF_Raw!I2:I1561,"") -> 11
A41: Blank as % of shifts | B41: =B40/B37 -> 0.014066496
A42: Cost per agency shift (£) | B42: 385 | C42: Supplied by Priya
A43: BEST case — all blanks are bank | B43: =B38*B42 -> 49280 | C43: Most likely: blanks arise from bank shifts booked outside the agency module
A44: CENTRAL — blanks agency at the flagged rate | B44: =(B38+B40*B38/(B38+B39))*B42 -> 49983.087
...

Sheet OP_Raw
A1: Appointment_ID | B1: NHS_Number | C1: Patient_Surname | D1: Patient_DOB | E1: Specialty_Code | F1: Consultant_Code | G1: Clinic_Code | H1: Appointment_Date | I1: Appointment_Time | J1: Attendance_Status | K1: Waiting_Days | L1: RTT_Status | M1: RTT_Weeks | N1: Referral_Source | O1: Postcode | P1: Waiting_Days_Validated | Q1: Waiting_Days_Check | R1: Specialty_Code_Clean
A2: APT-100001 | B2: 4823719056 | C2: AHMED | D2: 28564 | E2: GM | F2: C-1042 | G2: CL-101 | H2: 45663 | I2: 09:00 | J2: ATT | K2: 34 | L2: CLOSED | M2: 4.9 | N2: GP | O2: NG1 2AB | P2: =IF(AND(ISNUMBER(K2),K2>=0),K2,IF(ISNUMBER(M2),ROUND(M2*7,0),"")) -> 34 | Q2: =IF(ISTEXT(K2),"TEXT - recovered",IF(K2<0,"NEGATIVE",IF(K2>728,">104 WEEKS","OK"))) -> OK | R2: =IF(E2="GEN","GM",E2) -> GM
A3: APT-100002 | B3: 7612384905 | C3: PATEL | D3: 23945 | E3: CS | F3: C-1017 | G3: CL-102 | H3: 45663 | I3: 09:30 | J3: ATT | K3: 67 | L3: CLOSED | M3: 9.6 | N3: GP | O3: LE1 1AA | P3: =IF(AND(ISNUMBER(K3),K3>=0),K3,IF(ISNUMBER(M3),ROUND(M3*7,0),"")) -> 67 | Q3: =IF(ISTEXT(K3),"TEXT - recovered",IF(K3<0,"NEGATIVE",IF(K3>728,">104 WEEKS","OK"))) -> OK | R3: =IF(E3="GEN","GM",E3) -> CS
A4: APT-100003 | B4: 3394820174 | C4: WILSON | D4: 32820 | E4: OR | F4: C-1033 | G4: CL-103 | H4: 45663 | I4: 10:00 | J4: DNA | K4: 145 | L4: OPEN | M4: 20.7 | N4: GP | O4: NG5 3CD | P4: =IF(AND(ISNUMBER(K4),K4>=0),K4,IF(ISNUMBER(M4),ROUND(M4*7,0),"")) -> 145 | Q4: =IF(ISTEXT(K4),"TEXT - recovered",IF(K4<0,"NEGATIVE",IF(K4>728,">104 WEEKS","OK"))) -> OK | R4: =IF(E4="GEN","GM",E4) -> OR
A5: APT-100004 | B5: 9182746350 | C5: OKAFOR | D5: 26329 | E5: GS | F5: C-1028 | G5: CL-104 | H5: 45663 | I5: 10:30 | J5: ATT | K5: 28 | L5: CLOSED | M5: 4 | N5: CONS | O5: LE2 7GH | P5: =IF(AND(ISNUMBER(K5),K5>=0),K5,IF(ISNUMBER(M5),ROUND(M5*7,0),"")) -> 28 | Q5: =IF(ISTEXT(K5),"TEXT - recovered",IF(K5<0,"NEGATIVE",IF(K5>728,">104 WEEKS","OK"))) -> OK | R5: =IF(E5="GEN","GM",E5) -> GS
A6: APT-100005 | B6: 6547832901 | C6: KHAN | D6: 20620 | E6: RS | F6: C-1051 | G6: CL-105 | H6: 45663 | I6: 11:00 | J6: ATT | K6: 89 | L6: CLOSED | M6: 12.7 | N6: GP | O6: NG7 4EF | P6: =IF(AND(ISNUMBER(K6),K6>=0),K6,IF(ISNUMBER(M6),ROUND(M6*7,0),"")) -> 89 | Q6: =IF(ISTEXT(K6),"TEXT - recovered",IF(K6<0,"NEGATIVE",IF(K6>728,">104 WEEKS","OK"))) -> OK | R6: =IF(E6="GEN","GM",E6) -> RS
A7: APT-100006 | B7: 2938475610 | C7: SMITH | D7: 15952 | E7: EM | F7: C-1009 | G7: CL-106 | H7: 45663 | I7: 11:30 | J7: CAN | K7: 12 | L7: OPEN | M7: 1.7 | N7: ED | O7: NG1 5KL | P7: =IF(AND(ISNUMBER(K7),K7>=0),K7,IF(ISNUMBER(M7),ROUND(M7*7,0),"")) -> 12 | Q7: =IF(ISTEXT(K7),"TEXT - recovered",IF(K7<0,"NEGATIVE",IF(K7>728,">104 WEEKS","OK"))) -> OK | R7: =IF(E7="GEN","GM",E7) -> EM
A8: APT-100007 | B8: 8174629305 | C8: JONES | D8: 29703 | E8: GYN | F8: C-1044 | G8: CL-107 | H8: 45663 | I8: 13:00 | J8: ATT | K8: 56 | L8: CLOSED | M8: 8 | N8: GP | O8: LE4 2MN | P8: =IF(AND(ISNUMBER(K8),K8>=0),K8,IF(ISNUMBER(M8),ROUND(M8*7,0),"")) -> 56 | Q8: =IF(ISTEXT(K8),"TEXT - recovered",IF(K8<0,"NEGATIVE",IF(K8>728,">104 WEEKS","OK"))) -> OK | R8: =IF(E8="GEN","GM",E8) -> GYN
A9: APT-100008 | B9: 5063821749 | C9: WILLIAMS | D9: 34687 | E9: URO | F9: C-1022 | G9: CL-108 | H9: 45663 | I9: 13:30 | J9: DNA | K9: 178 | L9: OPEN | M9: 25.4 | N9: GP | O9: NG8 6PQ | P9: =IF(AND(ISNUMBER(K9),K9>=0),K9,IF(ISNUMBER(M9),ROUND(M9*7,0),"")) -> 178 | Q9: =IF(ISTEXT(K9),"TEXT - recovered",IF(K9<0,"NEGATIVE",IF(K9>728,">104 WEEKS","OK"))) -> OK | R9: =IF(E9="GEN","GM",E9) -> URO
A10: APT-100009 | B10: 1847362905 | C10: BROWN | D10: 24691 | E10: OPH | F10: C-1037 | G10: CL-109 | H10: 45663 | I10: 14:00 | J10: ATT | K10: 45 | L10: CLOSED | M10: 6.4 | N10: GP | O10: LE5 0RS | P10: =IF(AND(ISNUMBER(K10),K10>=0),K10,IF(ISNUMBER(M10),ROUND(M10*7,0),"")) -> 45 | Q10: =IF(ISTEXT(K10),"TEXT - recovered",IF(K10<0,"NEGATIVE",IF(K10>728,">104 WEEKS","OK"))) -> OK | R10: =IF(E10="GEN","GM",E10) -> OPH
A11: APT-100010 | B11: 4729183650 | C11: TAYLOR | D11: 19049 | E11: RHE | F11: C-1015 | G11: CL-110 | H11: 45663 | I11: 14:30 | J11: ATT | K11: 112 | L11: CLOSED | M11: 16 | N11: GP | O11: NG2 1TU | P11: =IF(AND(ISNUMBER(K11),K11>=0),K11,IF(ISNUMBER(M11),ROUND(M11*7,0),"")) -> 112 | Q11: =IF(ISTEXT(K11),"TEXT - recovered",IF(K11<0,"NEGATIVE",IF(K11>728,">104 WEEKS","OK"))) -> OK | R11: =IF(E11="GEN","GM",E11) -> RHE
A12: APT-100011 | B12: 3816294750 | C12: DAVIES | D12: 32427 | E12: GM | F12: C-1042 | G12: CL-101 | H12: 45664 | I12: 09:00 | J12: ATT | K12: 23 | L12: CLOSED | M12: 3.3 | N12: GP | O12: NG3 2VW | P12: =IF(AND(ISNUMBER(K12),K12>=0),K12,IF(ISNUMBER(M12),ROUND(M12*7,0),"")) -> 23 | Q12: =IF(ISTEXT(K12),"TEXT - recovered",IF(K12<0,"NEGATIVE",IF(K12>728,">104 WEEKS","OK"))) -> OK | R12: =IF(E12="GEN","GM",E12) -> GM
A13: APT-100012 | B13: 7294618305 | C13: EVANS | D13: 26814 | E13: CS | F13: C-1017 | G13: CL-102 | H13: 45664 | I13: 09:30 | J13: DNA | K13: 134 | L13: OPEN | M13: 19.1 | N13: GP | O13: LE6 1XY | P13: =IF(AND(ISNUMBER(K13),K13>=0),K13,IF(ISNUMBER(M13),ROUND(M13*7,0),"")) -> 134 | Q13: =IF(ISTEXT(K13),"TEXT - recovered",IF(K13<0,"NEGATIVE",IF(K13>728,">104 WEEKS","OK"))) -> OK | R13: =IF(E13="GEN","GM",E13) -> CS
... A153: APT-100152 | B153: 6291374056 | C153: RICE | D153: 27766 | E153: GYN | F153: C-1044 | G153: CL-107 | H153: 45684 | I153: 09:30 | J153: ATT | K153: 57 | L153: CLOSED | M153: 8.1 | N153: GP | O153: LE3 1NO | P153: =IF(AND(ISNUMBER(K153),K153>=0),K153,IF(ISNUMBER(M153),ROUND(M153*7,0),"")) -> 57 | Q153: =IF(ISTEXT(K153),"TEXT - recovered",IF(K153<0,"NEGATIVE",IF(K153>728,">104 WEEKS","OK"))) -> OK | R153: =IF(E153="GEN","GM",E153) -> GYN
A154: APT-100153 | C154: HASSAN | D154: 29329 | E154: GEN | F154: C-1033 | G154: CL-103 | H154: 45684 | I154: 10:00 | J154: ATT | K154: 78 | M154: 11.1 | N154: GP | O154: NG5 3CD | P154: =IF(AND(ISNUMBER(K154),K154>=0),K154,IF(ISNUMBER(M154),ROUND(M154*7,0),"")) -> 78 | Q154: =IF(ISTEXT(K154),"TEXT - recovered",IF(K154<0,"NEGATIVE",IF(K154>728,">104 WEEKS","OK"))) -> OK | R154: =IF(E154="GEN","GM",E154) -> GM
A155: APT-100154 | B155: 7184926350 | C155: NGUYEN | D155: 21492 | E155: CS | F155: C-1017 | G155: CL-102 | H155: 45684 | I155: 10:30 | J155: attended | K155: 34 | L155: CLOSED | M155: 4.9 | N155: GP | O155: LE1 1AA | P155: =IF(AND(ISNUMBER(K155),K155>=0),K155,IF(ISNUMBER(M155),ROUND(M155*7,0),"")) -> 34 | Q155: =IF(ISTEXT(K155),"TEXT - recovered",IF(K155<0,"NEGATIVE",IF(K155>728,">104 WEEKS","OK"))) -> OK | R155: =IF(E155="GEN","GM",E155) -> CS
A156: APT-100155 | B156: 3829174605 | C156: BROOKS | D156: 30112 | E156: GM | F156: C-1042 | G156: CL-101 | H156: 45684 | I156: 11:00 | J156: ATT | K156: 45 | L156: CLOSED | M156: 6.4 | N156: GP | O156: LE6 3LM | P156: =IF(AND(ISNUMBER(K156),K156>=0),K156,IF(ISNUMBER(M156),ROUND(M156*7,0),"")) -> 45 | Q156: =IF(ISTEXT(K156),"TEXT - recovered",IF(K156<0,"NEGATIVE",IF(K156>728,">104 WEEKS","OK"))) -> OK | R156: =IF(E156="GEN","GM",E156) -> GM
A157: APT-100156 | B157: 4819273650 | C157: OSEI | D157: 33444 | E157: OR | G157: CL-103 | H157: 45684 | I157: 11:30 | J157: DNA | K157: 145 | L157: OPEN | M157: 20.7 | N157: GP | P157: =IF(AND(ISNUMBER(K157),K157>=0),K157,IF(ISNUMBER(M157),ROUND(M157*7,0),"")) -> 145 | Q157: =IF(ISTEXT(K157),"TEXT - recovered",IF(K157<0,"NEGATIVE",IF(K157>728,">104 WEEKS","OK"))) -> OK | R157: =IF(E157="GEN","GM",E157) -> OR
A158: APT-100157 | B158: 2947163850 | C158: JACKSON | D158: 29102 | E158: GS | F158: C-1028 | G158: CL-104 | H158: 45684 | I158: 13:00 | J158: ATT | K158: 42 | L158: CLOSED | M158: 6 | N158: GP | O158: LE7 2BC | P158: =IF(AND(ISNUMBER(K158),K158>=0),K158,IF(ISNUMBER(M158),ROUND(M158*7,0),"")) -> 42 | Q158: =IF(ISTEXT(K158),"TEXT - recovered",IF(K158<0,"NEGATIVE",IF(K158>728,">104 WEEKS","OK"))) -> OK | R158: =IF(E158="GEN","GM",E158) -> GS
A159: APT-100158 | B159: 8163924750 | C159: MENSAH | D159: 23813 | E159: RS | F159: C-1051 | G159: CL-105 | H159: 45684 | I159: 13:30 | J159: DNA | K159: 189 | L159: OPEN | M159: 27 | N159: GP | O159: NG7 5CD | P159: =IF(AND(ISNUMBER(K159),K159>=0),K159,IF(ISNUMBER(M159),ROUND(M159*7,0),"")) -> 189 | Q159: =IF(ISTEXT(K159),"TEXT - recovered",IF(K159<0,"NEGATIVE",IF(K159>728,">104 WEEKS","OK"))) -> OK | R159: =IF(E159="GEN","GM",E159) -> RS
A160: APT-100159 | B160: 5948271630 | C160: ROBINSON | D160: 28087 | E160: RHE | F160: C-1015 | G160: CL-110 | H160: 45684 | I160: 14:00 | J160: DNA | K160: 168 | L160: OPEN | M160: 24 | N160: GP | O160: NG7 6NO | P160: =IF(AND(ISNUMBER(K160),K160>=0),K160,IF(ISNUMBER(M160),ROUND(M160*7,0),"")) -> 168 | Q160: =IF(ISTEXT(K160),"TEXT - recovered",IF(K160<0,"NEGATIVE",IF(K160>728,">104 WEEKS","OK"))) -> OK | R160: =IF(E160="GEN","GM",E160) -> RHE
A161: APT-100160 | B161: 6183924750 | C161: WHITE | D161: 16639 | E161: GEN | F161: C-1051 | G161: CL-105 | H161: 45684 | I161: 14:30 | J161: ATT | K161: 56 | L161: CLOSED | M161: 8 | N161: GP | O161: NG5 4DE | P161: =IF(AND(ISNUMBER(K161),K161>=0),K161,IF(ISNUMBER(M161),ROUND(M161*7,0),"")) -> 56 | Q161: =IF(ISTEXT(K161),"TEXT - recovered",IF(K161<0,"NEGATIVE",IF(K161>728,">104 WEEKS","OK"))) -> OK | R161: =IF(E161="GEN","GM",E161) -> GM
A162: APT-100161 | B162: 4273819605 | C162: WRIGHT | D162: 30898 | E162: GM | F162: C-1042 | G162: CL-101 | H162: 45685 | I162: 09:00 | J162: ATT | K162: 35 | L162: CLOSED | M162: 5 | N162: GP | O162: LE5 7JK | P162: =IF(AND(ISNUMBER(K162),K162>=0),K162,IF(ISNUMBER(M162),ROUND(M162*7,0),"")) -> 35 | Q162: =IF(ISTEXT(K162),"TEXT - recovered",IF(K162<0,"NEGATIVE",IF(K162>728,">104 WEEKS","OK"))) -> OK | R162: =IF(E162="GEN","GM",E162) -> GM
A163: APT-100162 | B163: 8149273650 | C163: SCOTT | D163: 24949 | E163: CS | F163: C-1017 | G163: CL-102 | H163: 45685 | I163: 09:30 | J163: DNA | K163: 202 | L163: OPEN | M163: 28.9 | N163: GP | O163: NG6 4LM | P163: =IF(AND(ISNUMBER(K163),K163>=0),K163,IF(ISNUMBER(M163),ROUND(M163*7,0),"")) -> 202 | Q163: =IF(ISTEXT(K163),"TEXT - recovered",IF(K163<0,"NEGATIVE",IF(K163>728,">104 WEEKS","OK"))) -> OK | R163: =IF(E163="GEN","GM",E163) -> CS
A164: APT-100163 | B164: 1847362905 | C164: DAVIES | D164: 32427 | E164: GM | F164: C-1042 | G164: CL-101 | H164: 45685 | I164: 10:00 | J164: ATT | K164: 24 | L164: CLOSED | M164: 3.4 | N164: GP | O164: NG3 2VW | P164: =IF(AND(ISNUMBER(K164),K164>=0),K164,IF(ISNUMBER(M164),ROUND(M164*7,0),"")) -> 24 | Q164: =IF(ISTEXT(K164),"TEXT - recovered",IF(K164<0,"NEGATIVE",IF(K164>728,">104 WEEKS","OK"))) -> OK | R164: =IF(E164="GEN","GM",E164) -> GM
A165: APT-100164 | C165: CHIRWA | D165: 25728 | E165: OR | F165: C-1033 | G165: CL-103 | H165: 45685 | I165: 10:30 | J165: DNA | K165: 267 | L165: OPEN | M165: 38.1 | N165: GP | O165: NG2 4TU | P165: =IF(AND(ISNUMBER(K165),K165>=0),K165,IF(ISNUMBER(M165),ROUND(M165*7,0),"")) -> 267 | Q165: =IF(ISTEXT(K165),"TEXT - recovered",IF(K165<0,"NEGATIVE",IF(K165>728,">104 WEEKS","OK"))) -> OK | R165: =IF(E165="GEN","GM",E165) -> OR
A166: APT-100165 | B166: 7294618305 | C166: EVANS | D166: 26814 | E166: CS | F166: C-1017 | G166: CL-102 | H166: 45685 | I166: 11:00 | J166: ATT | K166: 56 | L166: CLOSED | M166: 8 | N166: CONS | O166: LE6 1XY | P166: =IF(AND(ISNUMBER(K166),K166>=0),K166,IF(ISNUMBER(M166),ROUND(M166*7,0),"")) -> 56 | Q166: =IF(ISTEXT(K166),"TEXT - recovered",IF(K166<0,"NEGATIVE",IF(K166>728,">104 WEEKS","OK"))) -> OK | R166: =IF(E166="GEN","GM",E166) -> CS
A167: APT-100166 | B167: 3947821605 | C167: ADEYEMI | D167: 31460 | E167: GYN | F167: C-1044 | G167: CL-107 | H167: 45685 | I167: 11:30 | J167: ATT | K167: 34 | L167: CLOSED | M167: 4.9 | N167: GP | O167: LE4 2MN | P167: =IF(AND(ISNUMBER(K167),K167>=0),K167,IF(ISNUMBER(M167),ROUND(M167*7,0),"")) -> 34 | Q167: =IF(ISTEXT(K167),"TEXT - recovered",IF(K167<0,"NEGATIVE",IF(K167>728,">104 WEEKS","OK"))) -> OK | R167: =IF(E167="GEN","GM",E167) -> GYN
A168: APT-100167 | B168: 6374829105 | C168: NELSON | D168: 27168 | E168: GYN | F168: C-1044 | G168: CL-107 | H168: 45685 | I168: 13:00 | J168: ATT | K168: 46 | L168: CLOSED | M168: 6.6 | N168: GP | O168: LE8 4VW | P168: =IF(AND(ISNUMBER(K168),K168>=0),K168,IF(ISNUMBER(M168),ROUND(M168*7,0),"")) -> 46 | Q168: =IF(ISTEXT(K168),"TEXT - recovered",IF(K168<0,"NEGATIVE",IF(K168>728,">104 WEEKS","OK"))) -> OK | R168: =IF(E168="GEN","GM",E168) -> GYN
A169: APT-100168 | B169: 5183924760 | C169: WOOD | D169: 23329 | E169: EM | F169: C-1009 | G169: CL-106 | H169: 45685 | I169: 13:30 | J169: ATT | K169: 26 | L169: OPEN | M169: 3.7 | N169: ED | O169: NG5 5VW | P169: =IF(AND(ISNUMBER(K169),K169>=0),K169,IF(ISNUMBER(M169),ROUND(M169*7,0),"")) -> 26 | Q169: =IF(ISTEXT(K169),"TEXT - recovered",IF(K169<0,"NEGATIVE",IF(K169>728,">104 WEEKS","OK"))) -> OK | R169: =IF(E169="GEN","GM",E169) -> EM
A170: APT-100169 | B170: 8291736450 | C170: OKONKWO | D170: 29089 | E170: GS | G170: CL-104 | H170: 45685 | I170: 14:00 | J170: ATT | K170: 67 | L170: CLOSED | M170: 9.6 | N170: GP | O170: LE9 3NO | P170: =IF(AND(ISNUMBER(K170),K170>=0),K170,IF(ISNUMBER(M170),ROUND(M170*7,0),"")) -> 67 | Q170: =IF(ISTEXT(K170),"TEXT - recovered",IF(K170<0,"NEGATIVE",IF(K170>728,">104 WEEKS","OK"))) -> OK | R170: =IF(E170="GEN","GM",E170) -> GS
A171: APT-100170 | B171: 3748291605 | C171: PEREZ | D171: 26003 | E171: RHE | F171: C-1015 | G171: CL-110 | H171: 45685 | I171: 14:30 | J171: ATT | K171: 68 | L171: CLOSED | M171: 9.7 | N171: GP | O171: NG2 3BC | P171: =IF(AND(ISNUMBER(K171),K171>=0),K171,IF(ISNUMBER(M171),ROUND(M171*7,0),"")) -> 68 | Q171: =IF(ISTEXT(K171),"TEXT - recovered",IF(K171<0,"NEGATIVE",IF(K171>728,">104 WEEKS","OK"))) -> OK | R171: =IF(E171="GEN","GM",E171) -> RHE
A172: APT-100171 | B172: 5847291360 | C172: PATTERSON | D172: 32195 | E172: RS | F172: C-1051 | G172: CL-105 | H172: 45686 | I172: 09:00 | J172: ATT | K172: 46 | L172: CLOSED | M172: 6.6 | N172: GP | O172: LE4 5NO | P172: =IF(AND(ISNUMBER(K172),K172>=0),K172,IF(ISNUMBER(M172),ROUND(M172*7,0),"")) -> 46 | Q172: =IF(ISTEXT(K172),"TEXT - recovered",IF(K172<0,"NEGATIVE",IF(K172>728,">104 WEEKS","OK"))) -> OK | R172: =IF(E172="GEN","GM",E172) -> RS
A173: APT-100172 | B173: 2947163850 | C173: JACKSON | D173: 29102 | E173: GS | F173: C-1028 | G173: CL-104 | H173: 45686 | I173: 09:30 | J173: DNA | K173: 179 | L173: OPEN | M173: 25.6 | N173: GP | O173: LE7 2BC | P173: =IF(AND(ISNUMBER(K173),K173>=0),K173,IF(ISNUMBER(M173),ROUND(M173*7,0),"")) -> 179 | Q173: =IF(ISTEXT(K173),"TEXT - recovered",IF(K173<0,"NEGATIVE",IF(K173>728,">104 WEEKS","OK"))) -> OK | R173: =IF(E173="GEN","GM",E173) -> GS
A174: APT-100173 | B174: 4817293605 | C174: KELLY | D174: 28343 | E174: GYN | F174: C-1044 | G174: CL-107 | H174: 45686 | I174: 10:00 | J174: ATT | K174: 46 | L174: CLOSED | M174: 6.6 | N174: GP | O174: LE8 1JK | P174: =IF(AND(ISNUMBER(K174),K174>=0),K174,IF(ISNUMBER(M174),ROUND(M174*7,0),"")) -> 46 | Q174: =IF(ISTEXT(K174),"TEXT - recovered",IF(K174<0,"NEGATIVE",IF(K174>728,">104 WEEKS","OK"))) -> OK | R174: =IF(E174="GEN","GM",E174) -> GYN
A175: APT-100174 | B175: 9374821605 | C175: WATSON | D175: 25840 | E175: RHE | F175: C-1015 | G175: CL-110 | H175: 45686 | I175: 10:30 | J175: ATT | K175: 46 | L175: CLOSED | M175: 6.6 | N175: GP | O175: NG2 6JK | P175: =IF(AND(ISNUMBER(K175),K175>=0),K175,IF(ISNUMBER(M175),ROUND(M175*7,0),"")) -> 46 | Q175: =IF(ISTEXT(K175),"TEXT - recovered",IF(K175<0,"NEGATIVE",IF(K175>728,">104 WEEKS","OK"))) -> OK | R175: =IF(E175="GEN","GM",E175) -> RHE
A176: APT-100175 | C176: IHEJIRIKA | D176: 23206 | E176: GM | F176: C-1042 | G176: CL-101 | H176: 45686 | I176: 11:00 | J176: DNA | K176: 312 | L176: OPEN | M176: 44.6 | N176: GP | O176: NG1 2AB | P176: =IF(AND(ISNUMBER(K176),K176>=0),K176,IF(ISNUMBER(M176),ROUND(M176*7,0),"")) -> 312 | Q176: =IF(ISTEXT(K176),"TEXT - recovered",IF(K176<0,"NEGATIVE",IF(K176>728,">104 WEEKS","OK"))) -> OK | R176: =IF(E176="GEN","GM",E176) -> GM
A177: APT-100176 | B177: 6193847205 | C177: ALEXANDER | D177: 22432 | E177: GS | F177: C-1028 | G177: CL-104 | H177: 45686 | I177: 11:30 | J177: ATT | K177: 35 | L177: CLOSED | M177: 5 | N177: GP | O177: NG6 5FG | P177: =IF(AND(ISNUMBER(K177),K177>=0),K177,IF(ISNUMBER(M177),ROUND(M177*7,0),"")) -> 35 | Q177: =IF(ISTEXT(K177),"TEXT - recovered",IF(K177<0,"NEGATIVE",IF(K177>728,">104 WEEKS","OK"))) -> OK | R177: =IF(E177="GEN","GM",E177) -> GS
A178: APT-100177 | B178: 7491836250 | C178: ADAMS | D178: 29063 | E178: GS | F178: C-1028 | G178: CL-104 | H178: 45686 | I178: 13:00 | J178: ATT | K178: 57 | L178: CLOSED | M178: 8.1 | N178: GP | O178: NG7 5PQ | P178: =IF(AND(ISNUMBER(K178),K178>=0),K178,IF(ISNUMBER(M178),ROUND(M178*7,0),"")) -> 57 | Q178: =IF(ISTEXT(K178),"TEXT - recovered",IF(K178<0,"NEGATIVE",IF(K178>728,">104 WEEKS","OK"))) -> OK | R178: =IF(E178="GEN","GM",E178) -> GS
A179: APT-100178 | B179: 4938271560 | C179: HENRY | D179: 22681 | E179: RHE | F179: C-1015 | G179: CL-110 | H179: 45686 | I179: 13:30 | J179: ATT | K179: 113 | L179: CLOSED | M179: 16.1 | N179: GP | O179: NG2 9ZA | P179: =IF(AND(ISNUMBER(K179),K179>=0),K179,IF(ISNUMBER(M179),ROUND(M179*7,0),"")) -> 113 | Q179: =IF(ISTEXT(K179),"TEXT - recovered",IF(K179<0,"NEGATIVE",IF(K179>728,">104 WEEKS","OK"))) -> OK | R179: =IF(E179="GEN","GM",E179) -> RHE
...

Sheet IP_Raw
A1: Episode_ID | B1: NHS_Number | C1: Patient_Surname | D1: Patient_DOB | E1: Admission_Date | F1: Admission_Type | G1: Ward_Code | H1: Specialty_Code | I1: Discharge_Date | J1: Discharge_Method | K1: Length_of_Stay | L1: Readmission_Flag | M1: HRG_Code | N1: Bed_Days | O1: Consultant_Code | P1: ICD10_Code | Q1: OPCS4_Code | R1: Specialty_Code_Clean
A2: EP-10000001 | B2: 8079359782 | C2: GONZALEZ | D2: 32717 | E2: 45725 | F2: ELEC | G2: W-02 | H2: URO | I2: 45727 | J2: HOME | K2: 2 | L2: N | M2: DD44D | N2: 2 | O2: C-1022 | P2: J45 | Q2: W41 | R2: =IF(H2="GEN","GM",H2) -> URO
A3: EP-10000002 | B3: 8705932525 | C3: MITCHELL | D3: 21626 | E3: 45601 | F3: EMER | G3: W-01 | H3: RHE | I3: 45607 | J3: HOME | K3: 6 | L3: N | M3: GG77G | N3: 6 | O3: C-1015 | P3: K57 | Q3: J21 | R3: =IF(H3="GEN","GM",H3) -> RHE
A4: EP-10000003 | B4: 4161692845 | C4: ADEYEMI | D4: 26750 | E4: 45709 | F4: EMER | G4: W-02 | H4: URO | I4: 45715 | J4: HOME | K4: 6 | L4: N | M4: KK11K | N4: 6 | O4: C-1022 | P4: M79 | Q4: M02 | R4: =IF(H4="GEN","GM",H4) -> URO
A5: EP-10000004 | B5: 2341389994 | C5: TAYLOR | D5: 34806 | E5: 45604 | F5: ELEC | G5: W-03 | H5: OPH | I5: 45605 | J5: HOME | K5: 1 | L5: N | M5: QQ66Q | N5: 1 | O5: C-1037 | P5: J44 | R5: =IF(H5="GEN","GM",H5) -> OPH
A6: EP-10000005 | B6: 4679970246 | C6: RODRIGUEZ | D6: 20327 | E6: 45664 | F6: EMER | G6: W-06 | H6: GYN | I6: 45664 | J6: ABSENT | K6: 0 | L6: Y | N6: 0 | O6: C-1044 | P6: K57 | Q6: J19 | R6: =IF(H6="GEN","GM",H6) -> GYN
A7: EP-10000006 | B7: 2268018242 | C7: ADEYEMI | D7: 27091 | E7: 45600 | F7: EMER | G7: W-03 | H7: OPH | I7: 45603 | J7: HOME | K7: 3 | L7: N | M7: EE55E | N7: 3 | O7: C-1037 | P7: I21 | Q7: W43 | R7: =IF(H7="GEN","GM",H7) -> OPH
A8: EP-10000007 | B8: 3150983930 | C8: SANCHEZ | D8: 24735 | E8: 45595 | F8: ELEC | G8: W-04 | H8: CS | I8: 45597 | J8: HOME | K8: 2 | L8: N | M8: RR77R | N8: 2 | O8: C-1017 | P8: N13 | Q8: M01 | R8: =IF(H8="GEN","GM",H8) -> CS
A9: EP-10000008 | B9: 0170127706 | C9: HARRIS | D9: 25990 | E9: 45617 | F9: ELEC | G9: W-02 | H9: GS | I9: 45619 | J9: HOME | K9: 2 | L9: N | N9: 2 | O9: C-1028 | P9: M16 | Q9: W43 | R9: =IF(H9="GEN","GM",H9) -> GS
A10: EP-10000009 | B10: 8728080100 | C10: TAYLOR | D10: 17308 | E10: 45610 | F10: ELEC | G10: W-05 | H10: RS | I10: 45615 | J10: HOME | K10: 5 | L10: N | N10: 5 | O10: C-1051 | P10: J44 | Q10: K42 | R10: =IF(H10="GEN","GM",H10) -> RS
A11: EP-10000010 | B11: 7062962015 | C11: EVANS | D11: 30108 | E11: 45688 | F11: ELEC | G11: W-02 | H11: URO | I11: 45692 | J11: HOME | K11: 4 | L11: N | M11: TT99T | N11: 4 | O11: C-1022 | P11: M79 | Q11: M03 | R11: =IF(H11="GEN","GM",H11) -> URO
A12: EP-10000011 | B12: 8281489325 | C12: MARTIN | D12: 35281 | E12: 45700 | F12: EMER | G12: W-01 | H12: EM | I12: 45706 | J12: ABSENT | K12: 6 | L12: N | M12: HH88H | N12: 6 | O12: C-1009 | P12: K92 | Q12: M01 | R12: =IF(H12="GEN","GM",H12) -> EM
A13: EP-10000012 | B13: 7234309805 | C13: PATEL | D13: 20360 | E13: 45637 | F13: EMER | G13: W-02 | H13: URO | I13: 45638 | J13: HOME | K13: 1 | L13: N | M13: PP55P | N13: 1 | O13: C-1022 | P13: C34 | Q13: K40 | R13: =IF(H13="GEN","GM",H13) -> URO
A14: EP-10000013 | B14: 1043321819 | C14: EVANS | D14: 26925 | E14: 45623 | F14: ELEC | G14: W-01 | H14: EM | I14: 45628 | J14: HOME | K14: 5 | L14: N | M14: AA11A | N14: 5 | O14: C-1009 | P14: N20 | Q14: J21 | R14: =IF(H14="GEN","GM",H14) -> EM
A15: EP-10000014 | B15: 9091334123 | C15: HASSAN | D15: 19352 | E15: 45621 | F15: EMER | G15: W-02 | H15: GS | I15: 45625 | J15: HOME | K15: 4 | L15: N | M15: PP55P | N15: 4 | O15: C-1028 | P15: M79 | Q15: E89 | R15: =IF(H15="GEN","GM",H15) -> GS
